[2024-12-06T14:17:15.030+0000] {local_task_job_runner.py:123} INFO - ::group::Pre task execution logs
[2024-12-06T14:17:15.045+0000] {taskinstance.py:2613} INFO - Dependencies all met for dep_context=non-requeueable deps ti=<TaskInstance: telemadrid_schedule_scraper_v2.PushAllInOne scheduled__2016-03-09T14:14:00+00:00 [queued]>
[2024-12-06T14:17:15.051+0000] {taskinstance.py:2613} INFO - Dependencies all met for dep_context=requeueable deps ti=<TaskInstance: telemadrid_schedule_scraper_v2.PushAllInOne scheduled__2016-03-09T14:14:00+00:00 [queued]>
[2024-12-06T14:17:15.052+0000] {taskinstance.py:2866} INFO - Starting attempt 1 of 5
[2024-12-06T14:17:15.065+0000] {taskinstance.py:2889} INFO - Executing <Task(_PythonDecoratedOperator): PushAllInOne> on 2016-03-09 14:14:00+00:00
[2024-12-06T14:17:15.071+0000] {warnings.py:112} WARNING - /home/***/.local/lib/python3.12/site-packages/***/task/task_runner/standard_task_runner.py:70: DeprecationWarning: This process (pid=815) is multi-threaded, use of fork() may lead to deadlocks in the child.
  pid = os.fork()

[2024-12-06T14:17:15.072+0000] {standard_task_runner.py:72} INFO - Started process 842 to run task
[2024-12-06T14:17:15.074+0000] {standard_task_runner.py:104} INFO - Running: ['***', 'tasks', 'run', 'telemadrid_schedule_scraper_v2', 'PushAllInOne', 'scheduled__2016-03-09T14:14:00+00:00', '--job-id', '1433', '--raw', '--subdir', 'DAGS_FOLDER/dag_telemadrid_v2.py', '--cfg-path', '/tmp/tmp8ehcry03']
[2024-12-06T14:17:15.075+0000] {standard_task_runner.py:105} INFO - Job 1433: Subtask PushAllInOne
[2024-12-06T14:17:15.114+0000] {task_command.py:467} INFO - Running <TaskInstance: telemadrid_schedule_scraper_v2.PushAllInOne scheduled__2016-03-09T14:14:00+00:00 [running]> on host 6b4257da02f0
[2024-12-06T14:17:15.179+0000] {taskinstance.py:3132} INFO - Exporting env vars: AIRFLOW_CTX_DAG_OWNER='***' AIRFLOW_CTX_DAG_ID='telemadrid_schedule_scraper_v2' AIRFLOW_CTX_TASK_ID='PushAllInOne' AIRFLOW_CTX_EXECUTION_DATE='2016-03-09T14:14:00+00:00' AIRFLOW_CTX_TRY_NUMBER='1' AIRFLOW_CTX_DAG_RUN_ID='scheduled__2016-03-09T14:14:00+00:00'
[2024-12-06T14:17:15.180+0000] {taskinstance.py:731} INFO - ::endgroup::
[2024-12-06T14:17:19.846+0000] {logging_mixin.py:190} INFO - Error: 422 {"message": "Invalid request.\n\n\"sha\" wasn't supplied.", "documentation_url": "https://docs.github.com/rest/repos/contents#create-or-update-file-contents", "status": "422"}
[2024-12-06T14:17:19.847+0000] {python.py:240} INFO - Done. Returned value was: None
[2024-12-06T14:17:19.853+0000] {taskinstance.py:340} INFO - ::group::Post task execution logs
[2024-12-06T14:17:19.854+0000] {taskinstance.py:352} INFO - Marking task as SUCCESS. dag_id=telemadrid_schedule_scraper_v2, task_id=PushAllInOne, run_id=scheduled__2016-03-09T14:14:00+00:00, execution_date=20160309T141400, start_date=20241206T141715, end_date=20241206T141719
[2024-12-06T14:17:19.897+0000] {local_task_job_runner.py:266} INFO - Task exited with return code 0
[2024-12-06T14:17:19.906+0000] {taskinstance.py:3895} INFO - 0 downstream tasks scheduled from follow-on schedule check
[2024-12-06T14:17:19.907+0000] {local_task_job_runner.py:245} INFO - ::endgroup::
