[2024-12-06T11:31:26.539+0000] {local_task_job_runner.py:123} INFO - ::group::Pre task execution logs
[2024-12-06T11:31:26.550+0000] {taskinstance.py:2613} INFO - Dependencies all met for dep_context=non-requeueable deps ti=<TaskInstance: telemadrid_schedule_scraper_v2.PushAllInOne scheduled__2024-01-22T11:32:00+00:00 [queued]>
[2024-12-06T11:31:26.557+0000] {taskinstance.py:2613} INFO - Dependencies all met for dep_context=requeueable deps ti=<TaskInstance: telemadrid_schedule_scraper_v2.PushAllInOne scheduled__2024-01-22T11:32:00+00:00 [queued]>
[2024-12-06T11:31:26.557+0000] {taskinstance.py:2866} INFO - Starting attempt 1 of 5
[2024-12-06T11:31:26.572+0000] {taskinstance.py:2889} INFO - Executing <Task(_PythonDecoratedOperator): PushAllInOne> on 2024-01-22 11:32:00+00:00
[2024-12-06T11:31:26.577+0000] {warnings.py:112} WARNING - /home/***/.local/lib/python3.12/site-packages/***/task/task_runner/standard_task_runner.py:70: DeprecationWarning: This process (pid=352) is multi-threaded, use of fork() may lead to deadlocks in the child.
  pid = os.fork()

[2024-12-06T11:31:26.578+0000] {standard_task_runner.py:72} INFO - Started process 374 to run task
[2024-12-06T11:31:26.579+0000] {standard_task_runner.py:104} INFO - Running: ['***', 'tasks', 'run', 'telemadrid_schedule_scraper_v2', 'PushAllInOne', 'scheduled__2024-01-22T11:32:00+00:00', '--job-id', '747', '--raw', '--subdir', 'DAGS_FOLDER/dag_telemadrid_v2.py', '--cfg-path', '/tmp/tmpvuzw98qe']
[2024-12-06T11:31:26.581+0000] {standard_task_runner.py:105} INFO - Job 747: Subtask PushAllInOne
[2024-12-06T11:31:26.618+0000] {task_command.py:467} INFO - Running <TaskInstance: telemadrid_schedule_scraper_v2.PushAllInOne scheduled__2024-01-22T11:32:00+00:00 [running]> on host d88abb179e8d
[2024-12-06T11:31:26.672+0000] {taskinstance.py:3132} INFO - Exporting env vars: AIRFLOW_CTX_DAG_OWNER='***' AIRFLOW_CTX_DAG_ID='telemadrid_schedule_scraper_v2' AIRFLOW_CTX_TASK_ID='PushAllInOne' AIRFLOW_CTX_EXECUTION_DATE='2024-01-22T11:32:00+00:00' AIRFLOW_CTX_TRY_NUMBER='1' AIRFLOW_CTX_DAG_RUN_ID='scheduled__2024-01-22T11:32:00+00:00'
[2024-12-06T11:31:26.674+0000] {taskinstance.py:731} INFO - ::endgroup::
[2024-12-06T11:31:32.255+0000] {logging_mixin.py:190} INFO - Error: 422 {"message": "Invalid request.\n\n\"sha\" wasn't supplied.", "documentation_url": "https://docs.github.com/rest/repos/contents#create-or-update-file-contents", "status": "422"}
[2024-12-06T11:31:32.256+0000] {python.py:240} INFO - Done. Returned value was: None
[2024-12-06T11:31:32.262+0000] {taskinstance.py:340} INFO - ::group::Post task execution logs
[2024-12-06T11:31:32.263+0000] {taskinstance.py:352} INFO - Marking task as SUCCESS. dag_id=telemadrid_schedule_scraper_v2, task_id=PushAllInOne, run_id=scheduled__2024-01-22T11:32:00+00:00, execution_date=20240122T113200, start_date=20241206T113126, end_date=20241206T113132
[2024-12-06T11:31:32.311+0000] {local_task_job_runner.py:266} INFO - Task exited with return code 0
[2024-12-06T11:31:32.319+0000] {taskinstance.py:3895} INFO - 0 downstream tasks scheduled from follow-on schedule check
[2024-12-06T11:31:32.320+0000] {local_task_job_runner.py:245} INFO - ::endgroup::
