[2024-12-06T11:31:46.448+0000] {local_task_job_runner.py:123} INFO - ::group::Pre task execution logs
[2024-12-06T11:31:46.459+0000] {taskinstance.py:2613} INFO - Dependencies all met for dep_context=non-requeueable deps ti=<TaskInstance: telemadrid_schedule_scraper_v2.PushAllInOne scheduled__2024-02-11T11:32:00+00:00 [queued]>
[2024-12-06T11:31:46.464+0000] {taskinstance.py:2613} INFO - Dependencies all met for dep_context=requeueable deps ti=<TaskInstance: telemadrid_schedule_scraper_v2.PushAllInOne scheduled__2024-02-11T11:32:00+00:00 [queued]>
[2024-12-06T11:31:46.465+0000] {taskinstance.py:2866} INFO - Starting attempt 1 of 5
[2024-12-06T11:31:46.475+0000] {taskinstance.py:2889} INFO - Executing <Task(_PythonDecoratedOperator): PushAllInOne> on 2024-02-11 11:32:00+00:00
[2024-12-06T11:31:46.481+0000] {warnings.py:112} WARNING - /home/***/.local/lib/python3.12/site-packages/***/task/task_runner/standard_task_runner.py:70: DeprecationWarning: This process (pid=498) is multi-threaded, use of fork() may lead to deadlocks in the child.
  pid = os.fork()

[2024-12-06T11:31:46.482+0000] {standard_task_runner.py:72} INFO - Started process 505 to run task
[2024-12-06T11:31:46.483+0000] {standard_task_runner.py:104} INFO - Running: ['***', 'tasks', 'run', 'telemadrid_schedule_scraper_v2', 'PushAllInOne', 'scheduled__2024-02-11T11:32:00+00:00', '--job-id', '789', '--raw', '--subdir', 'DAGS_FOLDER/dag_telemadrid_v2.py', '--cfg-path', '/tmp/tmp0vcj4z6w']
[2024-12-06T11:31:46.484+0000] {standard_task_runner.py:105} INFO - Job 789: Subtask PushAllInOne
[2024-12-06T11:31:46.517+0000] {task_command.py:467} INFO - Running <TaskInstance: telemadrid_schedule_scraper_v2.PushAllInOne scheduled__2024-02-11T11:32:00+00:00 [running]> on host d88abb179e8d
[2024-12-06T11:31:46.572+0000] {taskinstance.py:3132} INFO - Exporting env vars: AIRFLOW_CTX_DAG_OWNER='***' AIRFLOW_CTX_DAG_ID='telemadrid_schedule_scraper_v2' AIRFLOW_CTX_TASK_ID='PushAllInOne' AIRFLOW_CTX_EXECUTION_DATE='2024-02-11T11:32:00+00:00' AIRFLOW_CTX_TRY_NUMBER='1' AIRFLOW_CTX_DAG_RUN_ID='scheduled__2024-02-11T11:32:00+00:00'
[2024-12-06T11:31:46.574+0000] {taskinstance.py:731} INFO - ::endgroup::
[2024-12-06T11:31:50.943+0000] {logging_mixin.py:190} INFO - Error: 422 {"message": "Invalid request.\n\n\"sha\" wasn't supplied.", "documentation_url": "https://docs.github.com/rest/repos/contents#create-or-update-file-contents", "status": "422"}
[2024-12-06T11:31:50.943+0000] {python.py:240} INFO - Done. Returned value was: None
[2024-12-06T11:31:50.950+0000] {taskinstance.py:340} INFO - ::group::Post task execution logs
[2024-12-06T11:31:50.951+0000] {taskinstance.py:352} INFO - Marking task as SUCCESS. dag_id=telemadrid_schedule_scraper_v2, task_id=PushAllInOne, run_id=scheduled__2024-02-11T11:32:00+00:00, execution_date=20240211T113200, start_date=20241206T113146, end_date=20241206T113150
[2024-12-06T11:31:50.986+0000] {local_task_job_runner.py:266} INFO - Task exited with return code 0
[2024-12-06T11:31:50.995+0000] {taskinstance.py:3895} INFO - 0 downstream tasks scheduled from follow-on schedule check
[2024-12-06T11:31:50.996+0000] {local_task_job_runner.py:245} INFO - ::endgroup::
